Workbook

Sheet Parameters
A1: Scoring Parameters - Chess Hallucination Evaluation
A2: 1. Category Weights (W_c) - ordered from most to least severe
A3: Category | B3: W_c | C3: Justification
A4: move_legality | B4: 8 | C4: Proposes / validates an illegal move - solution becomes null
A5: piece_placement | B5: 6 | C5: Wrong square stated - invalidates the entire analysis
A6: material | B6: 5 | C6: Wrong material balance - distorts strategic evaluation
A7: piece_relations | B7: 4 | C7: Wrong tactical relation: attack, pin, fork, discovered...
A8: geometry | B8: 3 | C8: Wrong spatial description: diagonal, file, rank, direction
A9: reasoning | B9: 2 | C9: Logical error in the strategic reasoning chain
A10: other | B10: 1 | C10: Miscellaneous minor error (default fallback)
A12: 2. Severity Multipliers (M_s)
A13: Severity | B13: M_s | C13: Description
A14: major | B14: 3 | C14: Completely wrong - changes the entire evaluation
A15: medium | B15: 2 | C15: Partially wrong or misleading
A16: minor / small | B16: 1 | C16: Minor inaccuracy, negligible impact on conclusion
A18: 3. Decay Factor (δ) - applied per additional hallucination in same (puzzle, category) group
A19: Parameter | B19: Value | C19: Rationale
A20: δ (delta) | B20: 0.7 | C20: Geometric decay: each additional error in the same (puzzle, category) group contributes 70% of the previous one. Convergence cap = W_c × M_s / (1−δ).
A22: MODEL | B22: FINAL SCORE | C22: TOTAL HALLUCINATIONS | D22: AVERAGE PENALTY / PUZZLE
A23: GEMINI | B23: {=ROUND(INDIRECT("'Puzzle Scores " & A23 & "'!D22"), 2)} -> 79.48 | C23: =COUNT(INDIRECT("'Calculations " & A23 & "'!B:B")) -> 48 | D23: {=ROUND(INDIRECT("'Puzzle Scores " & A23 & "'!C22"), 2)} -> 20.52
A24: GPT | B24: {=ROUND(INDIRECT("'Puzzle Scores " & A24 & "'!D22"), 2)} -> 66.1 | C24: =COUNT(INDIRECT("'Calculations " & A24 & "'!B:B")) -> 76 | D24: {=ROUND(INDIRECT("'Puzzle Scores " & A24 & "'!C22"), 2)} -> 33.97
A25: QWEN | B25: {=ROUND(INDIRECT("'Puzzle Scores " & A25 & "'!D22"), 2)} -> 62.46 | C25: =COUNT(INDIRECT("'Calculations " & A25 & "'!B:B")) -> 114 | D25: {=ROUND(INDIRECT("'Puzzle Scores " & A25 & "'!C22"), 2)} -> 37.54
A26: LLAMA | B26: {=ROUND(INDIRECT("'Puzzle Scores " & A26 & "'!D22"), 2)} -> 54.85 | C26: =COUNT(INDIRECT("'Calculations " & A26 & "'!B:B")) -> 131 | D26: {=ROUND(INDIRECT("'Puzzle Scores " & A26 & "'!C22"), 2)} -> 45.43
A27: OPUS | B27: {=ROUND(INDIRECT("'Puzzle Scores " & A27 & "'!D22"), 2)} -> 35.99 | C27: =COUNT(INDIRECT("'Calculations " & A27 & "'!B:B")) -> 223 | D27: {=ROUND(INDIRECT("'Puzzle Scores " & A27 & "'!C22"), 2)} -> 68.88
A28: KIMI | B28: {=ROUND(INDIRECT("'Puzzle Scores " & A28 & "'!D22"), 2)} -> 6.99 | C28: =COUNT(INDIRECT("'Calculations " & A28 & "'!B:B")) -> 191 | D28: {=ROUND(INDIRECT("'Puzzle Scores " & A28 & "'!C22"), 2)} -> 152.09
A29: DEEPSEEK | B29: {=ROUND(INDIRECT("'Puzzle Scores " & A29 & "'!D22"), 2)} -> 2.17 | C29: =COUNT(INDIRECT("'Calculations " & A29 & "'!B:B")) -> 358 | D29: {=ROUND(INDIRECT("'Puzzle Scores " & A29 & "'!C22"), 2)} -> 284.48

Sheet Interpretation Scale
B2: Score Interpretation Scale
B3: 90 - 100 | C3: Excellent | D3: Minimal or absent hallucinations - a reference model for chess explanations
B4: 75 - 89 | C4: Good | D4: A few isolated minor errors - generally reliable explanations
B5: 55 - 74 | C5: Acceptable | D5: Moderate-severity systematic errors - require human verification
B6: 35 - 54 | C6: Weak | D6: Frequent and/or severe hallucinations - unclear explanations
B7: 0 - 34 | C7: Critic | D7: Most of the explanations contain serious factual errors

Sheet Data OPUS
A1: model | B1: puzzle_id | C1: fen | D1: move | E1: original_claim | F1: hallucination_type | G1: fixed_claim | H1: potential_impact
A2: Opus 4.6 | B2: 1 | C2: 3rk2r/pp3p1p/1q2p1pb/3p4/3Q4/P1N1PB1P/1PP3P1/1R1R2K1 b k - 0 1 | E2: Notice that Black's dark-squared bishop on g6... wait, actually the bishop is on h6 (from the position) | F2: piece_placement | G2: Notice that Black's dark-squared bishop on h6 | H2: major
A3: Opus 4.6 | B3: 1 | C3: 3rk2r/pp3p1p/1q2p1pb/3p4/3Q4/P1N1PB1P/1PP3P1/1R1R2K1 b k - 0 1 | D3: Bxe3 | E3: The bishop takes the e3 pawn, and because the White king is on g1, this is a discovered... no, it's actually a direct check from the bishop on e3 to the king on g1 along the diagonal. | F3: reasoning | G3: The bishop takes the e3 pawn and checks the White king on g1 | H3: major
A4: Opus 4.6 | B4: 1 | C4: 3rk2r/pp3p1p/1q2p1pb/3p4/3Q4/P1N1PB1P/1PP3P1/1R1R2K1 b k - 0 1 | D4: Bxe3 | E4: This is a classic example of an "undermining sacrifice" or "removal of the guard" combined with a check. | F4: reasoning | G4: This is a classic example of an X-rayAttack | H4: minor
A5: Opus 4.6 | B5: 2 | C5: r2k3r/pp1b1p2/4p1pn/q2pP3/1b5p/1PNB1Q1P/PBP2P2/2KR2R1 w - - 4 20 | E5: Look at the d5 pawn — it's defended by the bishop on d7 | F5: piece_relations | H5: major
A6: Opus 4.6 | B6: 2 | C6: r2k3r/pp1b1p2/4p1pn/q2pP3/1b5p/1PNB1Q1P/PBP2P2/2KR2R1 w - - 4 20 | E6: a pawn break combination that dismantles Black's central pawn chain and exploits the overloaded d7 bishop. | F6: reasoning | G6: Bishop on d7 is not overloaded | H6: medium
A7: Opus 4.6 | B7: 2 | C7: r2k3r/pp1b1p2/4p1pn/q2pP3/1b5p/1PNB1Q1P/PBP2P2/2KR2R1 w - - 4 20 | D7: Nxd5 | E7: This is not just winning a pawn — it's a clearance sacrifice that opens the e-file and prepares the devastating e6 advance. | F7: geometry | G7: The sacrifice dooes not open the e-file (even if black recaptures, the e-file will be semi-open). It actually opens up the bishop on b2. | H7: medium
A8: Opus 4.6 | B8: 2 | C8: r2k3r/pp1b1p2/4p1pn/q2pP3/1b5p/1PNB1Q1P/PBP2P2/2KR2R1 w - - 4 20 | D8: exd5 | E8: Black recaptures, which is forced — ignoring the knight would simply leave White a pawn up with a dominant position. | F8: move_legality | G8: Recapturing with the pawn is not forced - a queen recapture is also possible | H8: minor
A9: Opus 4.6 | B9: 2 | C9: r2k3r/pp1b1p2/4p1pn/q2pP3/1b5p/1PNB1Q1P/PBP2P2/2KR2R1 w - - 4 20 | D9: e6 | E9: This is a classic pawn fork/deflection idea | F9: reasoning | G9: It is a discovered attack and a double attack - completely misses the fact that the bishop on b2 attacks the h8 rook | H9: major
A10: Opus 4.6 | B10: 2 | C10: r2k3r/pp1b1p2/4p1pn/q2pP3/1b5p/1PNB1Q1P/PBP2P2/2KR2R1 w - - 4 20 | D10: e6 | E10: Now Black faces a serious problem: the bishop must move or be captured, and wherever it goes, White's e6 pawn becomes a monster | F10: reasoning | G10: If the bishop moves, the rook on h8 will be captured by the bishop - completely misses that the bishop can capture the e6 pawn, so it will no longer "a monster" | H10: major
A11: Opus 4.6 | B11: 2 | C11: r2k3r/pp1b1p2/4p1pn/q2pP3/1b5p/1PNB1Q1P/PBP2P2/2KR2R1 w - - 4 20 | D11: e6 | E11: Notice also that the d-file is now open for White's rook on d1 | F11: geometry | G11: There is a black pawn on d5, so the d-file is not open | H11: medium
A12: Opus 4.6 | B12: 2 | C12: r2k3r/pp1b1p2/4p1pn/q2pP3/1b5p/1PNB1Q1P/PBP2P2/2KR2R1 w - - 4 20 | D12: Re8 | E12: Black tries to challenge the e-pawn by placing the rook on the e-file, but the advanced pawn is too strong. | F12: reasoning | G12: Black moves the rook because it is attacked and he wants to lose less points | H12: major
A13: Opus 4.6 | B13: 2 | C13: r2k3r/pp1b1p2/4p1pn/q2pP3/1b5p/1PNB1Q1P/PBP2P2/2KR2R1 w - - 4 20 | D13: exd7 | E13: and the pawn promotes... no, not yet — but the pawn on d7 is extraordinarily powerful. | F13: piece_placement | G13: The pawn captures the bishop on d7, it does not promote | H13: major
A14: Opus 4.6 | B14: 2 | C14: r2k3r/pp1b1p2/4p1pn/q2pP3/1b5p/1PNB1Q1P/PBP2P2/2KR2R1 w - - 4 20 | D14: exd7 | E14: It's one square from promotion and forces Black's king to deal with it personally. | F14: move_legality | G14: King is not forced to capture the pawn, the rook could move to prevent promotion on e8 | H14: minor
A15: Opus 4.6 | B15: 2 | C15: r2k3r/pp1b1p2/4p1pn/q2pP3/1b5p/1PNB1Q1P/PBP2P2/2KR2R1 w - - 4 20 | D15: Kxd7 | E15: The king stands on an open file (the d-file, where White has a rook!) | F15: geometry | G15: There is a black pawn on d5, so the d-file is not open | H15: major
A16: Opus 4.6 | B16: 2 | C16: r2k3r/pp1b1p2/4p1pn/q2pP3/1b5p/1PNB1Q1P/PBP2P2/2KR2R1 w - - 4 20 | E16: Advance the freed pawn to attack the defender (e6) | F16: piece_relations | G16: The bishop on d7 attacked by the move e6 is not defending anything | H16: medium
A17: Opus 4.6 | B17: 2 | C17: r2k3r/pp1b1p2/4p1pn/q2pP3/1b5p/1PNB1Q1P/PBP2P2/2KR2R1 w - - 4 20 | E17: This is a classic example of a "chain destruction" tactic combined with a deflection/exposure theme. | F17: reasoning | G17: Completely misses the discovered attack performed by the bishop on b2 | H17: major
A18: Opus 4.6 | B18: 3 | C18: 5k2/2nr1pp1/pb5p/1p2PP2/4N1R1/P3P2P/1B2K1P1/8 w - - 0 1 | E18: the knight on d7 | F18: piece_placement | G18: knigh is on c7 | H18: major
A19: Opus 4.6 | B19: 3 | C19: 5k2/2nr1pp1/pb5p/1p2PP2/4N1R1/P3P2P/1B2K1P1/8 w - - 0 1 | E19: rook on e7 | F19: piece_placement | G19: rook is on d7 | H19: major
A20: Opus 4.6 | B20: 3 | C20: 5k2/2nr1pp1/pb5p/1p2PP2/4N1R1/P3P2P/1B2K1P1/8 w - - 0 1 | E20: the knight on d7 and rook on e7 are lined up on the same diagonal/file | F20: geometry | G20: The knight and rook are on the same rank (7th) | H20: major
A21: Opus 4.6 | B21: 3 | C21: 5k2/2nr1pp1/pb5p/1p2PP2/4N1R1/P3P2P/1B2K1P1/8 w - - 0 1 | E21: can White exploit the g7 pawn, which is the main shield of Black's king? | F21: reasoning | G21: The pawns on f7 and g7 are protecting the king | H21: minor
A22: Opus 4.6 | B22: 3 | C22: 5k2/2nr1pp1/pb5p/1p2PP2/4N1R1/P3P2P/1B2K1P1/8 w - - 0 1 | E22: Notice that g7 is defended only by the king (f7 is pinned to nothing, but the pawn is there) | F22: reasoning | G22: The g7 pawn is only defended by the King, but unclear why it even mentiones f7? | H22: medium
A23: Opus 4.6 | B23: 3 | C23: 5k2/2nr1pp1/pb5p/1p2PP2/4N1R1/P3P2P/1B2K1P1/8 w - - 0 1 | D23: Rxg7 | E23: A rook sacrifice! White gives up the exchange (and more — a whole rook) | F23: material | G23: White sacrifices a rook for a pawn | H23: medium
A24: Opus 4.6 | B24: 3 | C24: 5k2/2nr1pp1/pb5p/1p2PP2/4N1R1/P3P2P/1B2K1P1/8 w - - 0 1 | D24: Rxg7 | E24: The idea is NOT just to win the g7 pawn, but to clear the way for the e-pawn to advance with devastating effect | F24: geometry | G24: Capturing the pawn on g7 does not clear the way for the pawn to advance, its trying to attract the king to g7 to prepare a discovered attack | H24: medium
A25: Opus 4.6 | B25: 3 | C25: 5k2/2nr1pp1/pb5p/1p2PP2/4N1R1/P3P2P/1B2K1P1/8 w - - 0 1 | D25: Rxg7 | E25: Ask yourself: "After the pawn advances, what happens to the pieces on the e-file and d-file?" | F25: piece_placement | G25: There is no black piece on the e-file | H25: minor
A26: Opus 4.6 | B26: 3 | C26: 5k2/2nr1pp1/pb5p/1p2PP2/4N1R1/P3P2P/1B2K1P1/8 w - - 0 1 | D26: Kxg7 | E26: Black has no real choice — declining the capture leaves White with an overwhelming attack on g7 and f7. | F26: reasoning | G26: Declining the capture leaves white with material advantage - there is no relevant attack on the g7 & f7 squares | H26: major
A27: Opus 4.6 | B27: 3 | C27: 5k2/2nr1pp1/pb5p/1p2PP2/4N1R1/P3P2P/1B2K1P1/8 w - - 0 1 | D27: 2. Rxf7 ?? | F27: reasoning | G27: move suggested by it, blunder | H27: medium
A28: Opus 4.6 | B28: 3 | C28: 5k2/2nr1pp1/pb5p/1p2PP2/4N1R1/P3P2P/1B2K1P1/8 w - - 0 1 | D28: 2...Kg8 ?? | F28: reasoning | G28: move suggested by it, blunder | H28: medium
A29: Opus 4.6 | B29: 3 | C29: 5k2/2nr1pp1/pb5p/1p2PP2/4N1R1/P3P2P/1B2K1P1/8 w - - 0 1 | D29: 3. Re7 ?? | F29: reasoning | G29: move suggested by it, blunder | H29: medium
A30: Opus 4.6 | B30: 3 | C30: 5k2/2nr1pp1/pb5p/1p2PP2/4N1R1/P3P2P/1B2K1P1/8 w - - 0 1 | D30: 3. Re7 ?? | E30: and White is winning with an extra exchange and dominant position. | F30: material | G30: white is losing - is 3 pawns up but will lose a rook | H30: medium
A31: Opus 4.6 | B31: 3 | C31: 5k2/2nr1pp1/pb5p/1p2PP2/4N1R1/P3P2P/1B2K1P1/8 w - - 0 1 | D31: e6+ | E31: The e-pawn storms forward with check (discovered check is not applicable here, but the pawn advance itself gives check by opening no line — actually, it's a direct pawn advance attacking f7 while the pawn on e6 attacks d7). Wait — let's be precise: e6+ is not actually check. Let me re-examine. | F31: reasoning | G31: e6 gives a discovered check. | H31: major
A32: Opus 4.6 | B32: 3 | C32: 5k2/2nr1pp1/pb5p/1p2PP2/4N1R1/P3P2P/1B2K1P1/8 w - - 0 1 | D32: e6+ | E32: meanwhile the pawn on e6 attacks the knight on d7 and threatens to capture it. | F32: piece_placement | G32: the pawn on e6 attacks the ROOK on d7 | H32: major
A33: Opus 4.6 | B33: 3 | C33: 5k2/2nr1pp1/pb5p/1p2PP2/4N1R1/P3P2P/1B2K1P1/8 w - - 0 1 | D33: Kf8 | E33: The king retreats to the only safe square | F33: move_legality | G33: there are other legal moves possible, like Kh7 or f6 | H33: medium
A34: Opus 4.6 | B34: 3 | C34: 5k2/2nr1pp1/pb5p/1p2PP2/4N1R1/P3P2P/1B2K1P1/8 w - - 0 1 | D34: Kf8 | E34: On Kf6?? Nf2 or Kh7, the king wanders into danger. | F34: move_legality | G34: no sure what its claim is here? | H34: major
A35: Opus 4.6 | B35: 3 | C35: 5k2/2nr1pp1/pb5p/1p2PP2/4N1R1/P3P2P/1B2K1P1/8 w - - 0 1 | D35: Kf8 | E35: the pawn is on e6, forking the knight | F35: piece_relations | G35: pawn is attacking the rook | H35: major
A36: Opus 4.6 | B36: 3 | C36: 5k2/2nr1pp1/pb5p/1p2PP2/4N1R1/P3P2P/1B2K1P1/8 w - - 0 1 | D36: exd7 | E36: White captures the knight | F36: piece_placement | G36: white captures the rook | H36: major
A37: Opus 4.6 | B37: 3 | C37: 5k2/2nr1pp1/pb5p/1p2PP2/4N1R1/P3P2P/1B2K1P1/8 w - - 0 1 | D37: exd7 | E37: Black's rook on e7 is now tied down to stopping d8=Q | F37: piece_placement | G37: no black rook on e7 present | H37: major
A38: Opus 4.6 | B38: 3 | C38: 5k2/2nr1pp1/pb5p/1p2PP2/4N1R1/P3P2P/1B2K1P1/8 w - - 0 1 | D38: exd7 | E38: White has won a piece (knight) in the transaction | F38: material | G38: white won 2 pawns | H38: major
A39: Opus 4.6 | B39: 3 | C39: 5k2/2nr1pp1/pb5p/1p2PP2/4N1R1/P3P2P/1B2K1P1/8 w - - 0 1 | D39: exd7 | E39: White sacrificed a rook (5 points) but won a pawn and a knight (1+3 = 4 points) | F39: material | G39: won a pawn and a rook | H39: major
A40: Opus 4.6 | B40: 5 | C40: 8/1p6/4N1pk/5n2/P7/1P3R2/2r4P/7K b - - 0 1 | D40: Kg2 | E40: Forced. The king must move to g2 as it is the only legal square. | F40: move_legality | G40: It is the only legal square for the king, but the rook could also block the check (Rf1) | H40: minor
...

Sheet Calculations OPUS
A1: Row Idx | B1: Puzzle ID | C1: Hallucination Type | D1: Impact (cleaned) | E1: W_c (weight) | F1: M_s (×severity) | G1: k (rank in group) | H1: δ^(k-1) (decay) | I1: P (penalty)
A2: 1 | B2: ='Data OPUS'!B2 -> 1 | C2: ='Data OPUS'!F2 -> piece_placement | D2: =LOWER(TRIM('Data OPUS'!H2)) -> major | E2: =IF(ISNUMBER(SEARCH("move_legality",C2)),Parameters!$B$4,IF(ISNUMBER(SEARCH("piece_placement",C2)),Parameters!$B$5,IF(ISNUMBER(SEARCH("material",C2)),Parameters!$B$6,IF(ISNUMBER(SEARCH("piece_relations",C2)),Parameters!$B$7,IF(ISNUMBER(SEARCH("geometry",C2)),Parameters!$B$8,IF(ISNUMBER(SEARCH("reasoning",C2)),Parameters!$B$9,Parameters!$B$10)))))) -> 6 | F2: =IF(D2="major",Parameters!$B$14,IF(D2="medium",Parameters!$B$15,Parameters!$B$16)) -> 3 | G2: =COUNTIFS($B$2:$B$224,B2,$C$2:$C$224,C2,$F$2:$F$224,">"&F2)+COUNTIFS($B$2:$B$224,B2,$C$2:$C$224,C2,$F$2:$F$224,F2,$A$2:$A$224,"<="&A2) -> 1 | H2: =Parameters!$B$20^(G2-1) -> 1 | I2: =E2*F2*H2 -> 18
A3: 2 | B3: ='Data OPUS'!B3 -> 1 | C3: ='Data OPUS'!F3 -> reasoning | D3: =LOWER(TRIM('Data OPUS'!H3)) -> major | E3: =IF(ISNUMBER(SEARCH("move_legality",C3)),Parameters!$B$4,IF(ISNUMBER(SEARCH("piece_placement",C3)),Parameters!$B$5,IF(ISNUMBER(SEARCH("material",C3)),Parameters!$B$6,IF(ISNUMBER(SEARCH("piece_relations",C3)),Parameters!$B$7,IF(ISNUMBER(SEARCH("geometry",C3)),Parameters!$B$8,IF(ISNUMBER(SEARCH("reasoning",C3)),Parameters!$B$9,Parameters!$B$10)))))) -> 2 | F3: =IF(D3="major",Parameters!$B$14,IF(D3="medium",Parameters!$B$15,Parameters!$B$16)) -> 3 | G3: =COUNTIFS($B$2:$B$224,B3,$C$2:$C$224,C3,$F$2:$F$224,">"&F3)+COUNTIFS($B$2:$B$224,B3,$C$2:$C$224,C3,$F$2:$F$224,F3,$A$2:$A$224,"<="&A3) -> 1 | H3: =Parameters!$B$20^(G3-1) -> 1 | I3: =E3*F3*H3 -> 6
A4: 3 | B4: ='Data OPUS'!B4 -> 1 | C4: ='Data OPUS'!F4 -> reasoning | D4: =LOWER(TRIM('Data OPUS'!H4)) -> minor | E4: =IF(ISNUMBER(SEARCH("move_legality",C4)),Parameters!$B$4,IF(ISNUMBER(SEARCH("piece_placement",C4)),Parameters!$B$5,IF(ISNUMBER(SEARCH("material",C4)),Parameters!$B$6,IF(ISNUMBER(SEARCH("piece_relations",C4)),Parameters!$B$7,IF(ISNUMBER(SEARCH("geometry",C4)),Parameters!$B$8,IF(ISNUMBER(SEARCH("reasoning",C4)),Parameters!$B$9,Parameters!$B$10)))))) -> 2 | F4: =IF(D4="major",Parameters!$B$14,IF(D4="medium",Parameters!$B$15,Parameters!$B$16)) -> 1 | G4: =COUNTIFS($B$2:$B$224,B4,$C$2:$C$224,C4,$F$2:$F$224,">"&F4)+COUNTIFS($B$2:$B$224,B4,$C$2:$C$224,C4,$F$2:$F$224,F4,$A$2:$A$224,"<="&A4) -> 2 | H4: =Parameters!$B$20^(G4-1) -> 0.7 | I4: =E4*F4*H4 -> 1.4
A5: 4 | B5: ='Data OPUS'!B5 -> 2 | C5: ='Data OPUS'!F5 -> piece_relations | D5: =LOWER(TRIM('Data OPUS'!H5)) -> major | E5: =IF(ISNUMBER(SEARCH("move_legality",C5)),Parameters!$B$4,IF(ISNUMBER(SEARCH("piece_placement",C5)),Parameters!$B$5,IF(ISNUMBER(SEARCH("material",C5)),Parameters!$B$6,IF(ISNUMBER(SEARCH("piece_relations",C5)),Parameters!$B$7,IF(ISNUMBER(SEARCH("geometry",C5)),Parameters!$B$8,IF(ISNUMBER(SEARCH("reasoning",C5)),Parameters!$B$9,Parameters!$B$10)))))) -> 4 | F5: =IF(D5="major",Parameters!$B$14,IF(D5="medium",Parameters!$B$15,Parameters!$B$16)) -> 3 | G5: =COUNTIFS($B$2:$B$224,B5,$C$2:$C$224,C5,$F$2:$F$224,">"&F5)+COUNTIFS($B$2:$B$224,B5,$C$2:$C$224,C5,$F$2:$F$224,F5,$A$2:$A$224,"<="&A5) -> 1 | H5: =Parameters!$B$20^(G5-1) -> 1 | I5: =E5*F5*H5 -> 12
A6: 5 | B6: ='Data OPUS'!B6 -> 2 | C6: ='Data OPUS'!F6 -> reasoning | D6: =LOWER(TRIM('Data OPUS'!H6)) -> medium | E6: =IF(ISNUMBER(SEARCH("move_legality",C6)),Parameters!$B$4,IF(ISNUMBER(SEARCH("piece_placement",C6)),Parameters!$B$5,IF(ISNUMBER(SEARCH("material",C6)),Parameters!$B$6,IF(ISNUMBER(SEARCH("piece_relations",C6)),Parameters!$B$7,IF(ISNUMBER(SEARCH("geometry",C6)),Parameters!$B$8,IF(ISNUMBER(SEARCH("reasoning",C6)),Parameters!$B$9,Parameters!$B$10)))))) -> 2 | F6: =IF(D6="major",Parameters!$B$14,IF(D6="medium",Parameters!$B$15,Parameters!$B$16)) -> 2 | G6: =COUNTIFS($B$2:$B$224,B6,$C$2:$C$224,C6,$F$2:$F$224,">"&F6)+COUNTIFS($B$2:$B$224,B6,$C$2:$C$224,C6,$F$2:$F$224,F6,$A$2:$A$224,"<="&A6) -> 5 | H6: =Parameters!$B$20^(G6-1) -> 0.2401 | I6: =E6*F6*H6 -> 0.9604
A7: 6 | B7: ='Data OPUS'!B7 -> 2 | C7: ='Data OPUS'!F7 -> geometry | D7: =LOWER(TRIM('Data OPUS'!H7)) -> medium | E7: =IF(ISNUMBER(SEARCH("move_legality",C7)),Parameters!$B$4,IF(ISNUMBER(SEARCH("piece_placement",C7)),Parameters!$B$5,IF(ISNUMBER(SEARCH("material",C7)),Parameters!$B$6,IF(ISNUMBER(SEARCH("piece_relations",C7)),Parameters!$B$7,IF(ISNUMBER(SEARCH("geometry",C7)),Parameters!$B$8,IF(ISNUMBER(SEARCH("reasoning",C7)),Parameters!$B$9,Parameters!$B$10)))))) -> 3 | F7: =IF(D7="major",Parameters!$B$14,IF(D7="medium",Parameters!$B$15,Parameters!$B$16)) -> 2 | G7: =COUNTIFS($B$2:$B$224,B7,$C$2:$C$224,C7,$F$2:$F$224,">"&F7)+COUNTIFS($B$2:$B$224,B7,$C$2:$C$224,C7,$F$2:$F$224,F7,$A$2:$A$224,"<="&A7) -> 2 | H7: =Parameters!$B$20^(G7-1) -> 0.7 | I7: =E7*F7*H7 -> 4.2
A8: 7 | B8: ='Data OPUS'!B8 -> 2 | C8: ='Data OPUS'!F8 -> move_legality | D8: =LOWER(TRIM('Data OPUS'!H8)) -> minor | E8: =IF(ISNUMBER(SEARCH("move_legality",C8)),Parameters!$B$4,IF(ISNUMBER(SEARCH("piece_placement",C8)),Parameters!$B$5,IF(ISNUMBER(SEARCH("material",C8)),Parameters!$B$6,IF(ISNUMBER(SEARCH("piece_relations",C8)),Parameters!$B$7,IF(ISNUMBER(SEARCH("geometry",C8)),Parameters!$B$8,IF(ISNUMBER(SEARCH("reasoning",C8)),Parameters!$B$9,Parameters!$B$10)))))) -> 8 | F8: =IF(D8="major",Parameters!$B$14,IF(D8="medium",Parameters!$B$15,Parameters!$B$16)) -> 1 | G8: =COUNTIFS($B$2:$B$224,B8,$C$2:$C$224,C8,$F$2:$F$224,">"&F8)+COUNTIFS($B$2:$B$224,B8,$C$2:$C$224,C8,$F$2:$F$224,F8,$A$2:$A$224,"<="&A8) -> 1 | H8: =Parameters!$B$20^(G8-1) -> 1 | I8: =E8*F8*H8 -> 8
A9: 8 | B9: ='Data OPUS'!B9 -> 2 | C9: ='Data OPUS'!F9 -> reasoning | D9: =LOWER(TRIM('Data OPUS'!H9)) -> major | E9: =IF(ISNUMBER(SEARCH("move_legality",C9)),Parameters!$B$4,IF(ISNUMBER(SEARCH("piece_placement",C9)),Parameters!$B$5,IF(ISNUMBER(SEARCH("material",C9)),Parameters!$B$6,IF(ISNUMBER(SEARCH("piece_relations",C9)),Parameters!$B$7,IF(ISNUMBER(SEARCH("geometry",C9)),Parameters!$B$8,IF(ISNUMBER(SEARCH("reasoning",C9)),Parameters!$B$9,Parameters!$B$10)))))) -> 2 | F9: =IF(D9="major",Parameters!$B$14,IF(D9="medium",Parameters!$B$15,Parameters!$B$16)) -> 3 | G9: =COUNTIFS($B$2:$B$224,B9,$C$2:$C$224,C9,$F$2:$F$224,">"&F9)+COUNTIFS($B$2:$B$224,B9,$C$2:$C$224,C9,$F$2:$F$224,F9,$A$2:$A$224,"<="&A9) -> 1 | H9: =Parameters!$B$20^(G9-1) -> 1 | I9: =E9*F9*H9 -> 6
A10: 9 | B10: ='Data OPUS'!B10 -> 2 | C10: ='Data OPUS'!F10 -> reasoning | D10: =LOWER(TRIM('Data OPUS'!H10)) -> major | E10: =IF(ISNUMBER(SEARCH("move_legality",C10)),Parameters!$B$4,IF(ISNUMBER(SEARCH("piece_placement",C10)),Parameters!$B$5,IF(ISNUMBER(SEARCH("material",C10)),Parameters!$B$6,IF(ISNUMBER(SEARCH("piece_relations",C10)),Parameters!$B$7,IF(ISNUMBER(SEARCH("geometry",C10)),Parameters!$B$8,IF(ISNUMBER(SEARCH("reasoning",C10)),Parameters!$B$9,Parameters!$B$10)))))) -> 2 | F10: =IF(D10="major",Parameters!$B$14,IF(D10="medium",Parameters!$B$15,Parameters!$B$16)) -> 3 | G10: =COUNTIFS($B$2:$B$224,B10,$C$2:$C$224,C10,$F$2:$F$224,">"&F10)+COUNTIFS($B$2:$B$224,B10,$C$2:$C$224,C10,$F$2:$F$224,F10,$A$2:$A$224,"<="&A10) -> 2 | H10: =Parameters!$B$20^(G10-1) -> 0.7 | I10: =E10*F10*H10 -> 4.2
A11: 10 | B11: ='Data OPUS'!B11 -> 2 | C11: ='Data OPUS'!F11 -> geometry | D11: =LOWER(TRIM('Data OPUS'!H11)) -> medium | E11: =IF(ISNUMBER(SEARCH("move_legality",C11)),Parameters!$B$4,IF(ISNUMBER(SEARCH("piece_placement",C11)),Parameters!$B$5,IF(ISNUMBER(SEARCH("material",C11)),Parameters!$B$6,IF(ISNUMBER(SEARCH("piece_relations",C11)),Parameters!$B$7,IF(ISNUMBER(SEARCH("geometry",C11)),Parameters!$B$8,IF(ISNUMBER(SEARCH("reasoning",C11)),Parameters!$B$9,Parameters!$B$10)))))) -> 3 | F11: =IF(D11="major",Parameters!$B$14,IF(D11="medium",Parameters!$B$15,Parameters!$B$16)) -> 2 | G11: =COUNTIFS($B$2:$B$224,B11,$C$2:$C$224,C11,$F$2:$F$224,">"&F11)+COUNTIFS($B$2:$B$224,B11,$C$2:$C$224,C11,$F$2:$F$224,F11,$A$2:$A$224,"<="&A11) -> 3 | H11: =Parameters!$B$20^(G11-1) -> 0.49 | I11: =E11*F11*H11 -> 2.94
A12: 11 | B12: ='Data OPUS'!B12 -> 2 | C12: ='Data OPUS'!F12 -> reasoning | D12: =LOWER(TRIM('Data OPUS'!H12)) -> major | E12: =IF(ISNUMBER(SEARCH("move_legality",C12)),Parameters!$B$4,IF(ISNUMBER(SEARCH("piece_placement",C12)),Parameters!$B$5,IF(ISNUMBER(SEARCH("material",C12)),Parameters!$B$6,IF(ISNUMBER(SEARCH("piece_relations",C12)),Parameters!$B$7,IF(ISNUMBER(SEARCH("geometry",C12)),Parameters!$B$8,IF(ISNUMBER(SEARCH("reasoning",C12)),Parameters!$B$9,Parameters!$B$10)))))) -> 2 | F12: =IF(D12="major",Parameters!$B$14,IF(D12="medium",Parameters!$B$15,Parameters!$B$16)) -> 3 | G12: =COUNTIFS($B$2:$B$224,B12,$C$2:$C$224,C12,$F$2:$F$224,">"&F12)+COUNTIFS($B$2:$B$224,B12,$C$2:$C$224,C12,$F$2:$F$224,F12,$A$2:$A$224,"<="&A12) -> 3 | H12: =Parameters!$B$20^(G12-1) -> 0.49 | I12: =E12*F12*H12 -> 2.94
A13: 12 | B13: ='Data OPUS'!B13 -> 2 | C13: ='Data OPUS'!F13 -> piece_placement | D13: =LOWER(TRIM('Data OPUS'!H13)) -> major | E13: =IF(ISNUMBER(SEARCH("move_legality",C13)),Parameters!$B$4,IF(ISNUMBER(SEARCH("piece_placement",C13)),Parameters!$B$5,IF(ISNUMBER(SEARCH("material",C13)),Parameters!$B$6,IF(ISNUMBER(SEARCH("piece_relations",C13)),Parameters!$B$7,IF(ISNUMBER(SEARCH("geometry",C13)),Parameters!$B$8,IF(ISNUMBER(SEARCH("reasoning",C13)),Parameters!$B$9,Parameters!$B$10)))))) -> 6 | F13: =IF(D13="major",Parameters!$B$14,IF(D13="medium",Parameters!$B$15,Parameters!$B$16)) -> 3 | G13: =COUNTIFS($B$2:$B$224,B13,$C$2:$C$224,C13,$F$2:$F$224,">"&F13)+COUNTIFS($B$2:$B$224,B13,$C$2:$C$224,C13,$F$2:$F$224,F13,$A$2:$A$224,"<="&A13) -> 1 | H13: =Parameters!$B$20^(G13-1) -> 1 | I13: =E13*F13*H13 -> 18
... A224: 223 | B224: ='Data OPUS'!B224 -> 4 | C224: ='Data OPUS'!F224 -> reasoning | D224: =LOWER(TRIM('Data OPUS'!H224)) -> medium | E224: =IF(ISNUMBER(SEARCH("move_legality",C224)),Parameters!$B$4,IF(ISNUMBER(SEARCH("piece_placement",C224)),Parameters!$B$5,IF(ISNUMBER(SEARCH("material",C224)),Parameters!$B$6,IF(ISNUMBER(SEARCH("piece_relations",C224)),Parameters!$B$7,IF(ISNUMBER(SEARCH("geometry",C224)),Parameters!$B$8,IF(ISNUMBER(SEARCH("reasoning",C224)),Parameters!$B$9,Parameters!$B$10)))))) -> 2 | F224: =IF(D224="major",Parameters!$B$14,IF(D224="medium",Parameters!$B$15,Parameters!$B$16)) -> 2 | G224: =COUNTIFS($B$2:$B$224,B224,$C$2:$C$224,C224,$F$2:$F$224,">"&F224)+COUNTIFS($B$2:$B$224,B224,$C$2:$C$224,C224,$F$2:$F$224,F224,$A$2:$A$224,"<="&A224) -> 4 | H224: =Parameters!$B$20^(G224-1) -> 0.343 | I224: =E224*F224*H224 -> 1.372

Sheet Puzzle Scores OPUS
A1: Puzzle ID | B1: Hallucinations (count) | C1: P_total (sum of penalties) | D1: Score_p = MAX(0, 100−P_total) | E1: Interpretation
A2: 1 | B2: =COUNTIF('Calculations OPUS'!$B:$B, A2) -> 3 | C2: =SUMIF('Calculations OPUS'!$B:$B, A2, 'Calculations OPUS'!$I:$I) -> 25.4 | D2: =MAX(0,100-C2) -> 74.6 | E2: =IF(D2>=90,"Excellent",IF(D2>=75,"Good",IF(D2>=55,"Acceptable",IF(D2>=35,"Weak","Critic")))) -> Acceptable
A3: 2 | B3: =COUNTIF('Calculations OPUS'!$B:$B, A3) -> 13 | C3: =SUMIF('Calculations OPUS'!$B:$B, A3, 'Calculations OPUS'!$I:$I) -> 81.4984 | D3: =MAX(0,100-C3) -> 18.5016 | E3: =IF(D3>=90,"Excellent",IF(D3>=75,"Good",IF(D3>=55,"Acceptable",IF(D3>=35,"Weak","Critic")))) -> Critic
A4: 3 | B4: =COUNTIF('Calculations OPUS'!$B:$B, A4) -> 22 | C4: =SUMIF('Calculations OPUS'!$B:$B, A4, 'Calculations OPUS'!$I:$I) -> 160.5542 | D4: =MAX(0,100-C4) -> 0 | E4: =IF(D4>=90,"Excellent",IF(D4>=75,"Good",IF(D4>=55,"Acceptable",IF(D4>=35,"Weak","Critic")))) -> Critic
A5: 4 | B5: =COUNTIF('Calculations OPUS'!$B:$B, A5) -> 11 | C5: =SUMIF('Calculations OPUS'!$B:$B, A5, 'Calculations OPUS'!$I:$I) -> 48.748347 | D5: =MAX(0,100-C5) -> 51.251653 | E5: =IF(D5>=90,"Excellent",IF(D5>=75,"Good",IF(D5>=55,"Acceptable",IF(D5>=35,"Weak","Critic")))) -> Weak
A6: 5 | B6: =COUNTIF('Calculations OPUS'!$B:$B, A6) -> 8 | C6: =SUMIF('Calculations OPUS'!$B:$B, A6, 'Calculations OPUS'!$I:$I) -> 75.85 | D6: =MAX(0,100-C6) -> 24.15 | E6: =IF(D6>=90,"Excellent",IF(D6>=75,"Good",IF(D6>=55,"Acceptable",IF(D6>=35,"Weak","Critic")))) -> Critic
A7: 6 | B7: =COUNTIF('Calculations OPUS'!$B:$B, A7) -> 17 | C7: =SUMIF('Calculations OPUS'!$B:$B, A7, 'Calculations OPUS'!$I:$I) -> 65.154815 | D7: =MAX(0,100-C7) -> 34.845185 | E7: =IF(D7>=90,"Excellent",IF(D7>=75,"Good",IF(D7>=55,"Acceptable",IF(D7>=35,"Weak","Critic")))) -> Critic
A8: 7 | B8: =COUNTIF('Calculations OPUS'!$B:$B, A8) -> 4 | C8: =SUMIF('Calculations OPUS'!$B:$B, A8, 'Calculations OPUS'!$I:$I) -> 17.16 | D8: =MAX(0,100-C8) -> 82.84 | E8: =IF(D8>=90,"Excellent",IF(D8>=75,"Good",IF(D8>=55,"Acceptable",IF(D8>=35,"Weak","Critic")))) -> Good
A9: 8 | B9: =COUNTIF('Calculations OPUS'!$B:$B, A9) -> 18 | C9: =SUMIF('Calculations OPUS'!$B:$B, A9, 'Calculations OPUS'!$I:$I) -> 106.98409 | D9: =MAX(0,100-C9) -> 0 | E9: =IF(D9>=90,"Excellent",IF(D9>=75,"Good",IF(D9>=55,"Acceptable",IF(D9>=35,"Weak","Critic")))) -> Critic
A10: 9 | B10: =COUNTIF('Calculations OPUS'!$B:$B, A10) -> 14 | C10: =SUMIF('Calculations OPUS'!$B:$B, A10, 'Calculations OPUS'!$I:$I) -> 56.802323 | D10: =MAX(0,100-C10) -> 43.197677 | E10: =IF(D10>=90,"Excellent",IF(D10>=75,"Good",IF(D10>=55,"Acceptable",IF(D10>=35,"Weak","Critic")))) -> Weak
A11: 10 | B11: =COUNTIF('Calculations OPUS'!$B:$B, A11) -> 9 | C11: =SUMIF('Calculations OPUS'!$B:$B, A11, 'Calculations OPUS'!$I:$I) -> 66.62 | D11: =MAX(0,100-C11) -> 33.38 | E11: =IF(D11>=90,"Excellent",IF(D11>=75,"Good",IF(D11>=55,"Acceptable",IF(D11>=35,"Weak","Critic")))) -> Critic
A12: 11 | B12: =COUNTIF('Calculations OPUS'!$B:$B, A12) -> 3 | C12: =SUMIF('Calculations OPUS'!$B:$B, A12, 'Calculations OPUS'!$I:$I) -> 33 | D12: =MAX(0,100-C12) -> 67 | E12: =IF(D12>=90,"Excellent",IF(D12>=75,"Good",IF(D12>=55,"Acceptable",IF(D12>=35,"Weak","Critic")))) -> Acceptable
A13: 12 | B13: =COUNTIF('Calculations OPUS'!$B:$B, A13) -> 6 | C13: =SUMIF('Calculations OPUS'!$B:$B, A13, 'Calculations OPUS'!$I:$I) -> 30.7 | D13: =MAX(0,100-C13) -> 69.3 | E13: =IF(D13>=90,"Excellent",IF(D13>=75,"Good",IF(D13>=55,"Acceptable",IF(D13>=35,"Weak","Critic")))) -> Acceptable
... A21: 20 | B21: =COUNTIF('Calculations OPUS'!$B:$B, A21) -> 6 | C21: =SUMIF('Calculations OPUS'!$B:$B, A21, 'Calculations OPUS'!$I:$I) -> 31.132 | D21: =MAX(0,100-C21) -> 68.868 | E21: =IF(D21>=90,"Excellent",IF(D21>=75,"Good",IF(D21>=55,"Acceptable",IF(D21>=35,"Weak","Critic")))) -> Acceptable
A22: MODEL SCORE | C22: =ROUND(AVERAGE(C2:C21),2) -> 68.88 | D22: =ROUND(AVERAGE(D2:D21),2) -> 35.99 | E22: =IF(D22>=90,"Excellent",IF(D22>=75,"Good",IF(D22>=55,"Acceptable",IF(D22>=35,"Weak","Critic")))) -> Weak

Sheet Data LLAMA
A1: model | B1: puzzle_id | C1: fen | D1: move | E1: original_claim | F1: hallucination_type | G1: fixed_claim | H1: potential_impact
A2: Llama 4 Maverick | B2: 1 | C2: 3rk2r/pp3p1p/1q2p1pb/3p4/3Q4/P1N1PB1P/1PP3P1/1R1R2K1 b k - 0 1 | D2: Be3 | E2: putting White's King in a potentially vulnerable position. | F2: reasoning | G2: white's issue is not so much the king, but rather the queen | H2: minor
A3: Llama 4 Maverick | B3: 1 | D3: Qxe3 | E3: White is forced to recapture to address the check. | F3: move_legality | G3: white is not forced | H3: medium
A4: Llama 4 Maverick | B4: 1 | D4: 2...Qxe3 | E4: Now, Black can play Qxe3+, again putting the White King in check and potentially exploiting the exposed position of the White King. | F4: reasoning | G4: white's problem & the entire point of the tactic was the queen capture | H4: major
A5: Llama 4 Maverick | B5: 4 | C5: r2nkb1r/3b1ppp/4pn2/1B2p3/8/4BN2/PPP2PPP/2KR3R w kq - 0 1 | D5: Nxd7 | E5: notice that Black's position is somewhat compromised due to the somewhat undeveloped state | F5: reasoning | G5: does not state any particular facts | H5: medium
A6: Llama 4 Maverick | B6: 4 | D6: Nxd7 | E6: White starts with a sacrifice to expose Black's King and gain a strategic advantage. | F6: reasoning | G6: the point of the sacrifice was not to get strategic advantage, but to use the pin & open d-file to win material | H6: medium
A7: Llama 4 Maverick | B7: 4 | D7: Rd1 | E7: White develops the Rook to a potentially powerful open file and puts pressure on Black's position, especially on the d-file. | F7: reasoning | G7: white puts the rook on the d-file to put pressure on the pinned knight placced on the d-file | H7: medium
A8: Llama 4 Maverick | B8: 4 | D8: Rd1 | E8: This move also helps in controlling the d-file, which can be crucial in exerting influence over Black's position. | F8: reasoning | G8: repeats itself & still fails to mention the pinned knight | H8: minor
A9: Llama 4 Maverick | B9: 4 | E9: Black attempts to develop the Rook and put it on a relatively safe square, | F9: reasoning | G9: a5 is a safe sqaure for the rook | H9: minor
A10: Llama 4 Maverick | B10: 4 | D10: Bxd7 | E10: The Bishop on d7 is a strong piece that pins the Knight against the King | F10: piece_placement | G10: it no longer pins the knight, it just captured it | H10: major
A11: Llama 4 Maverick | B11: 4 | D11: Bxd7 | E11: gaining a material advantage or a strong initiative. | F11: reasoning | G11: it does gain a material advantage, period. it's trying to not make any clear claims in order to avoid making mistakes | H11: major
A12: Llama 4 Maverick | B12: 5 | C12: 8/1p6/4N1pk/5n2/P7/1P3R2/2r4P/7K b - - 0 1 | D12: Rc1 | E12: The first move in the sequence starts with a check, forcing White's king to move. | F12: move_legality | G12: moving the king is not the only legal move | H12: medium
A13: Llama 4 Maverick | B13: 5 | D13: Kg2 | E13: White's king moves to g2, likely to escape the check | F13: reasoning | G13: it is clear it moves to escape te check | H13: medium
A14: Llama 4 Maverick | B14: 5 | D14: Nh4+ | E14: This is a classic example of using a knight fork or simply checking to gain a tempo or create a weakness. | F14: reasoning | G14: it is a simple knight fork and is used to gain material, not a "tempo" | H14: major
A15: Llama 4 Maverick | B15: 5 | D15: Kg3 | E15: The king moves again, trying to avoid the check and possibly prepare for other defensive or counter-attacking measures. | F15: reasoning | G15: king moves because it is forced to | H15: major
A16: Llama 4 Maverick | B16: 5 | D16: Nxf3 | E16: not only captures material but also illustrates the concept of removing the defender | F16: reasoning | G16: it only wins material, nothing else | H16: major
A17: Llama 4 Maverick | B17: 5 | D17: Nxf3 | E17: a crucial piece that was potentially holding Black's position together | F17: reasoning | G17: the rook was white's, it cannot logicaly hold black's position together | H17: major
A18: Llama 4 Maverick | B18: 5 | D18: Kxf3 | E18: likely due to being the most straightforward recapture | F18: move_legality | G18: it is the ONLY possible recapture | H18: major
A19: Llama 4 Maverick | B19: 5 | D19: Kxf3 | E19: the alternative captures or moves might not have been more appealing. | F19: move_legality | G19: it is the ONLY possible recapture | H19: major
A20: Llama 4 Maverick | B20: 5 | D20: Kxf3 | E20: White recaptures with the king, likely due to being the most straightforward recapture | F20: reasoning | G20: it recaptures to try to reduce black's material advantage | H20: major
A21: Llama 4 Maverick | B21: 6 | C21: r2r2k1/pb1nbppp/1p2p3/4P3/7q/PBN1B3/1P2QPPP/2RR2K1 w - - 0 1 | D21: Rd4 | E21: notices that Black's Queen is somewhat exposed and can potentially be deflected | F21: reasoning | G21: deflection is not present | H21: major
A22: Llama 4 Maverick | B22: 6 | D22: Qxd4 | E22: Black is forced to capture the Rook | F22: move_legality | G22: not forced, black has other legal moves | H22: medium
A23: Llama 4 Maverick | B23: 6 | D23: Qxd4 | E23: as it is a relatively safe capture | F23: reasoning | G23: not a safe capture at all - loses the queen | H23: major
A24: Llama 4 Maverick | B24: 6 | D24: Qxd4 | E24: not doing so might allow White to further intensify the pressure | F24: reasoning | G24: not doing so will still lose the queen, he has no option of not losing the queen | H24: major
A25: Llama 4 Maverick | B25: 6 | D25: Bxd4 | E25: The Bishop on d4 is well-placed, potentially exerting influence over the diagonal | F25: reasoning | G25: bishop position is not relevant whatsoever | H25: minor
A26: Llama 4 Maverick | B26: 6 | D26: Bxd4 | E26: This sequence demonstrates a basic tactical procedure where a piece is sacrificed (in this case, the Rook) | F26: reasoning | G26: rook was not sacrificed, it was protected by the bishop | H26: major
A27: Llama 4 Maverick | B27: 6 | D27: Bxd4 | E27: The key pattern recognition here involves identifying the potential for a deflection sacrifice | F27: reasoning | G27: completely misses the puzzle theme: trapping the queen | H27: major
A28: Llama 4 Maverick | B28: 7 | C28: 5rk1/3r1p1p/pq4p1/2R1Q3/1p2P2P/3P4/PP1K2P1/5R2 b - - 0 1 | D28: f6 | E28: The first move is a quiet one | F28: reasoning | G28: it is not quiet, it attacks the queen | H28: major
A29: Llama 4 Maverick | B29: 7 | D29: f6 | E29: The move f6 prepares to potentially exploit this | F29: reasoning | G29: it does not "prepare" to exploit it, it litteraly does exploit it | H29: medium
A30: Llama 4 Maverick | B30: 7 | D30: f6 | E30: The move f6 prepares to potentially exploit this by removing a potential weakness | F30: reasoning | G30: what weakness is it removing?? | H30: major
A31: Llama 4 Maverick | B31: 7 | D31: f6 | E31: The move f6 prepares to potentially exploit this by slightly improving Black's position. | F31: reasoning | G31: it wins material, so it improves the position decisively | H31: medium
A32: Llama 4 Maverick | B32: 7 | D32: Qf4 | E32: White responds by moving their Queen to a more active square | F32: reasoning | G32: f4 is not a more active square | H32: minor
A33: Llama 4 Maverick | B33: 7 | D33: Qf4 | E33: potentially preparing to exert more influence over the board | F33: reasoning | G33: the queen move was forced by the attack, it does not prepare for anything | H33: minor
A34: Llama 4 Maverick | B34: 7 | D34: Qf4 | E34: However, this move also maintains the Queen's role in defending the c5-Rook. | F34: piece_relations | G34: queen on f4 does not defend the rook | H34: major
A35: Llama 4 Maverick | B35: 7 | D35: Qxc5 | E35: White's Queen, now on f4, is not in a position to immediately recapture due to the pin that would be created against their King. | F35: piece_relations | G35: there is no pin.; the queen cannot recapture because it is not a legal move | H35: major
A36: Llama 4 Maverick | B36: 7 | D36: Qxc5 | E36: This move demonstrates a basic tactical theme: removing a defender or taking advantage of a piece's limited mobility. | F36: reasoning | G36: removing the defender is correct, put limited mobility not | H36: medium
A37: Llama 4 Maverick | B37: 8 | C37: 5r2/1rp2pkp/3qbp2/8/1b6/1Q2N1P1/PP2PP1P/2RR2K1 w - - 0 1 | D37: Rd6 | E37: This move exploits the fact that Black's Queen is not well-supported and is on the same diagonal as the White Rook on d1. | F37: geometry | G37: same file | H37: major
A38: Llama 4 Maverick | B38: 8 | D38: Rd6 | E38: we are winning the Black Queen, as it's pinned against the King | F38: piece_relations | G38: there is no pin | H38: major
A39: Llama 4 Maverick | B39: 8 | D39: Rd6 | E39: after Nf5+, Black's Bishop on f5 will be blocking the f-file | F39: reasoning | G39: it is not blocking the f-file, and it is completely irrelevant too | H39: major
A40: Llama 4 Maverick | B40: 8 | D40: Rd6 | E40: the e6-Bishop is somewhat restricting the d6-square | F40: piece_placement | G40: he just said the bishop is on f5 after recapturing, so it cannot be on e6 too | H40: major
...

Sheet Calculations LLAMA
A1: Row Idx | B1: Puzzle ID | C1: Hallucination Type | D1: Impact (cleaned) | E1: W_c (weight) | F1: M_s (×severity) | G1: k (rank in group) | H1: δ^(k-1) (decay) | I1: P (penalty)
A2: 1 | B2: ='Data LLAMA'!B2 -> 1 | C2: ='Data LLAMA'!F2 -> reasoning | D2: =LOWER(TRIM('Data LLAMA'!H2)) -> minor | E2: =IF(ISNUMBER(SEARCH("move_legality",C2)),Parameters!$B$4,IF(ISNUMBER(SEARCH("piece_placement",C2)),Parameters!$B$5,IF(ISNUMBER(SEARCH("material",C2)),Parameters!$B$6,IF(ISNUMBER(SEARCH("piece_relations",C2)),Parameters!$B$7,IF(ISNUMBER(SEARCH("geometry",C2)),Parameters!$B$8,IF(ISNUMBER(SEARCH("reasoning",C2)),Parameters!$B$9,Parameters!$B$10)))))) -> 2 | F2: =IF(D2="major",Parameters!$B$14,IF(D2="medium",Parameters!$B$15,Parameters!$B$16)) -> 1 | G2: =COUNTIFS($B$2:$B$132,B2,$C$2:$C$132,C2,$F$2:$F$132,">"&F2)+COUNTIFS($B$2:$B$132,B2,$C$2:$C$132,C2,$F$2:$F$132,F2,$A$2:$A$132,"<="&A2) -> 2 | H2: =Parameters!$B$20^(G2-1) -> 0.7 | I2: =E2*F2*H2 -> 1.4
A3: 2 | B3: ='Data LLAMA'!B3 -> 1 | C3: ='Data LLAMA'!F3 -> move_legality | D3: =LOWER(TRIM('Data LLAMA'!H3)) -> medium | E3: =IF(ISNUMBER(SEARCH("move_legality",C3)),Parameters!$B$4,IF(ISNUMBER(SEARCH("piece_placement",C3)),Parameters!$B$5,IF(ISNUMBER(SEARCH("material",C3)),Parameters!$B$6,IF(ISNUMBER(SEARCH("piece_relations",C3)),Parameters!$B$7,IF(ISNUMBER(SEARCH("geometry",C3)),Parameters!$B$8,IF(ISNUMBER(SEARCH("reasoning",C3)),Parameters!$B$9,Parameters!$B$10)))))) -> 8 | F3: =IF(D3="major",Parameters!$B$14,IF(D3="medium",Parameters!$B$15,Parameters!$B$16)) -> 2 | G3: =COUNTIFS($B$2:$B$132,B3,$C$2:$C$132,C3,$F$2:$F$132,">"&F3)+COUNTIFS($B$2:$B$132,B3,$C$2:$C$132,C3,$F$2:$F$132,F3,$A$2:$A$132,"<="&A3) -> 1 | H3: =Parameters!$B$20^(G3-1) -> 1 | I3: =E3*F3*H3 -> 16
A4: 3 | B4: ='Data LLAMA'!B4 -> 1 | C4: ='Data LLAMA'!F4 -> reasoning | D4: =LOWER(TRIM('Data LLAMA'!H4)) -> major | E4: =IF(ISNUMBER(SEARCH("move_legality",C4)),Parameters!$B$4,IF(ISNUMBER(SEARCH("piece_placement",C4)),Parameters!$B$5,IF(ISNUMBER(SEARCH("material",C4)),Parameters!$B$6,IF(ISNUMBER(SEARCH("piece_relations",C4)),Parameters!$B$7,IF(ISNUMBER(SEARCH("geometry",C4)),Parameters!$B$8,IF(ISNUMBER(SEARCH("reasoning",C4)),Parameters!$B$9,Parameters!$B$10)))))) -> 2 | F4: =IF(D4="major",Parameters!$B$14,IF(D4="medium",Parameters!$B$15,Parameters!$B$16)) -> 3 | G4: =COUNTIFS($B$2:$B$132,B4,$C$2:$C$132,C4,$F$2:$F$132,">"&F4)+COUNTIFS($B$2:$B$132,B4,$C$2:$C$132,C4,$F$2:$F$132,F4,$A$2:$A$132,"<="&A4) -> 1 | H4: =Parameters!$B$20^(G4-1) -> 1 | I4: =E4*F4*H4 -> 6
A5: 4 | B5: ='Data LLAMA'!B5 -> 4 | C5: ='Data LLAMA'!F5 -> reasoning | D5: =LOWER(TRIM('Data LLAMA'!H5)) -> medium | E5: =IF(ISNUMBER(SEARCH("move_legality",C5)),Parameters!$B$4,IF(ISNUMBER(SEARCH("piece_placement",C5)),Parameters!$B$5,IF(ISNUMBER(SEARCH("material",C5)),Parameters!$B$6,IF(ISNUMBER(SEARCH("piece_relations",C5)),Parameters!$B$7,IF(ISNUMBER(SEARCH("geometry",C5)),Parameters!$B$8,IF(ISNUMBER(SEARCH("reasoning",C5)),Parameters!$B$9,Parameters!$B$10)))))) -> 2 | F5: =IF(D5="major",Parameters!$B$14,IF(D5="medium",Parameters!$B$15,Parameters!$B$16)) -> 2 | G5: =COUNTIFS($B$2:$B$132,B5,$C$2:$C$132,C5,$F$2:$F$132,">"&F5)+COUNTIFS($B$2:$B$132,B5,$C$2:$C$132,C5,$F$2:$F$132,F5,$A$2:$A$132,"<="&A5) -> 2 | H5: =Parameters!$B$20^(G5-1) -> 0.7 | I5: =E5*F5*H5 -> 2.8
A6: 5 | B6: ='Data LLAMA'!B6 -> 4 | C6: ='Data LLAMA'!F6 -> reasoning | D6: =LOWER(TRIM('Data LLAMA'!H6)) -> medium | E6: =IF(ISNUMBER(SEARCH("move_legality",C6)),Parameters!$B$4,IF(ISNUMBER(SEARCH("piece_placement",C6)),Parameters!$B$5,IF(ISNUMBER(SEARCH("material",C6)),Parameters!$B$6,IF(ISNUMBER(SEARCH("piece_relations",C6)),Parameters!$B$7,IF(ISNUMBER(SEARCH("geometry",C6)),Parameters!$B$8,IF(ISNUMBER(SEARCH("reasoning",C6)),Parameters!$B$9,Parameters!$B$10)))))) -> 2 | F6: =IF(D6="major",Parameters!$B$14,IF(D6="medium",Parameters!$B$15,Parameters!$B$16)) -> 2 | G6: =COUNTIFS($B$2:$B$132,B6,$C$2:$C$132,C6,$F$2:$F$132,">"&F6)+COUNTIFS($B$2:$B$132,B6,$C$2:$C$132,C6,$F$2:$F$132,F6,$A$2:$A$132,"<="&A6) -> 3 | H6: =Parameters!$B$20^(G6-1) -> 0.49 | I6: =E6*F6*H6 -> 1.96
A7: 6 | B7: ='Data LLAMA'!B7 -> 4 | C7: ='Data LLAMA'!F7 -> reasoning | D7: =LOWER(TRIM('Data LLAMA'!H7)) -> medium | E7: =IF(ISNUMBER(SEARCH("move_legality",C7)),Parameters!$B$4,IF(ISNUMBER(SEARCH("piece_placement",C7)),Parameters!$B$5,IF(ISNUMBER(SEARCH("material",C7)),Parameters!$B$6,IF(ISNUMBER(SEARCH("piece_relations",C7)),Parameters!$B$7,IF(ISNUMBER(SEARCH("geometry",C7)),Parameters!$B$8,IF(ISNUMBER(SEARCH("reasoning",C7)),Parameters!$B$9,Parameters!$B$10)))))) -> 2 | F7: =IF(D7="major",Parameters!$B$14,IF(D7="medium",Parameters!$B$15,Parameters!$B$16)) -> 2 | G7: =COUNTIFS($B$2:$B$132,B7,$C$2:$C$132,C7,$F$2:$F$132,">"&F7)+COUNTIFS($B$2:$B$132,B7,$C$2:$C$132,C7,$F$2:$F$132,F7,$A$2:$A$132,"<="&A7) -> 4 | H7: =Parameters!$B$20^(G7-1) -> 0.343 | I7: =E7*F7*H7 -> 1.372
A8: 7 | B8: ='Data LLAMA'!B8 -> 4 | C8: ='Data LLAMA'!F8 -> reasoning | D8: =LOWER(TRIM('Data LLAMA'!H8)) -> minor | E8: =IF(ISNUMBER(SEARCH("move_legality",C8)),Parameters!$B$4,IF(ISNUMBER(SEARCH("piece_placement",C8)),Parameters!$B$5,IF(ISNUMBER(SEARCH("material",C8)),Parameters!$B$6,IF(ISNUMBER(SEARCH("piece_relations",C8)),Parameters!$B$7,IF(ISNUMBER(SEARCH("geometry",C8)),Parameters!$B$8,IF(ISNUMBER(SEARCH("reasoning",C8)),Parameters!$B$9,Parameters!$B$10)))))) -> 2 | F8: =IF(D8="major",Parameters!$B$14,IF(D8="medium",Parameters!$B$15,Parameters!$B$16)) -> 1 | G8: =COUNTIFS($B$2:$B$132,B8,$C$2:$C$132,C8,$F$2:$F$132,">"&F8)+COUNTIFS($B$2:$B$132,B8,$C$2:$C$132,C8,$F$2:$F$132,F8,$A$2:$A$132,"<="&A8) -> 5 | H8: =Parameters!$B$20^(G8-1) -> 0.2401 | I8: =E8*F8*H8 -> 0.4802
A9: 8 | B9: ='Data LLAMA'!B9 -> 4 | C9: ='Data LLAMA'!F9 -> reasoning | D9: =LOWER(TRIM('Data LLAMA'!H9)) -> minor | E9: =IF(ISNUMBER(SEARCH("move_legality",C9)),Parameters!$B$4,IF(ISNUMBER(SEARCH("piece_placement",C9)),Parameters!$B$5,IF(ISNUMBER(SEARCH("material",C9)),Parameters!$B$6,IF(ISNUMBER(SEARCH("piece_relations",C9)),Parameters!$B$7,IF(ISNUMBER(SEARCH("geometry",C9)),Parameters!$B$8,IF(ISNUMBER(SEARCH("reasoning",C9)),Parameters!$B$9,Parameters!$B$10)))))) -> 2 | F9: =IF(D9="major",Parameters!$B$14,IF(D9="medium",Parameters!$B$15,Parameters!$B$16)) -> 1 | G9: =COUNTIFS($B$2:$B$132,B9,$C$2:$C$132,C9,$F$2:$F$132,">"&F9)+COUNTIFS($B$2:$B$132,B9,$C$2:$C$132,C9,$F$2:$F$132,F9,$A$2:$A$132,"<="&A9) -> 6 | H9: =Parameters!$B$20^(G9-1) -> 0.16807 | I9: =E9*F9*H9 -> 0.33614
A10: 9 | B10: ='Data LLAMA'!B10 -> 4 | C10: ='Data LLAMA'!F10 -> piece_placement | D10: =LOWER(TRIM('Data LLAMA'!H10)) -> major | E10: =IF(ISNUMBER(SEARCH("move_legality",C10)),Parameters!$B$4,IF(ISNUMBER(SEARCH("piece_placement",C10)),Parameters!$B$5,IF(ISNUMBER(SEARCH("material",C10)),Parameters!$B$6,IF(ISNUMBER(SEARCH("piece_relations",C10)),Parameters!$B$7,IF(ISNUMBER(SEARCH("geometry",C10)),Parameters!$B$8,IF(ISNUMBER(SEARCH("reasoning",C10)),Parameters!$B$9,Parameters!$B$10)))))) -> 6 | F10: =IF(D10="major",Parameters!$B$14,IF(D10="medium",Parameters!$B$15,Parameters!$B$16)) -> 3 | G10: =COUNTIFS($B$2:$B$132,B10,$C$2:$C$132,C10,$F$2:$F$132,">"&F10)+COUNTIFS($B$2:$B$132,B10,$C$2:$C$132,C10,$F$2:$F$132,F10,$A$2:$A$132,"<="&A10) -> 1 | H10: =Parameters!$B$20^(G10-1) -> 1 | I10: =E10*F10*H10 -> 18
A11: 10 | B11: ='Data LLAMA'!B11 -> 4 | C11: ='Data LLAMA'!F11 -> reasoning | D11: =LOWER(TRIM('Data LLAMA'!H11)) -> major | E11: =IF(ISNUMBER(SEARCH("move_legality",C11)),Parameters!$B$4,IF(ISNUMBER(SEARCH("piece_placement",C11)),Parameters!$B$5,IF(ISNUMBER(SEARCH("material",C11)),Parameters!$B$6,IF(ISNUMBER(SEARCH("piece_relations",C11)),Parameters!$B$7,IF(ISNUMBER(SEARCH("geometry",C11)),Parameters!$B$8,IF(ISNUMBER(SEARCH("reasoning",C11)),Parameters!$B$9,Parameters!$B$10)))))) -> 2 | F11: =IF(D11="major",Parameters!$B$14,IF(D11="medium",Parameters!$B$15,Parameters!$B$16)) -> 3 | G11: =COUNTIFS($B$2:$B$132,B11,$C$2:$C$132,C11,$F$2:$F$132,">"&F11)+COUNTIFS($B$2:$B$132,B11,$C$2:$C$132,C11,$F$2:$F$132,F11,$A$2:$A$132,"<="&A11) -> 1 | H11: =Parameters!$B$20^(G11-1) -> 1 | I11: =E11*F11*H11 -> 6
A12: 11 | B12: ='Data LLAMA'!B12 -> 5 | C12: ='Data LLAMA'!F12 -> move_legality | D12: =LOWER(TRIM('Data LLAMA'!H12)) -> medium | E12: =IF(ISNUMBER(SEARCH("move_legality",C12)),Parameters!$B$4,IF(ISNUMBER(SEARCH("piece_placement",C12)),Parameters!$B$5,IF(ISNUMBER(SEARCH("material",C12)),Parameters!$B$6,IF(ISNUMBER(SEARCH("piece_relations",C12)),Parameters!$B$7,IF(ISNUMBER(SEARCH("geometry",C12)),Parameters!$B$8,IF(ISNUMBER(SEARCH("reasoning",C12)),Parameters!$B$9,Parameters!$B$10)))))) -> 8 | F12: =IF(D12="major",Parameters!$B$14,IF(D12="medium",Parameters!$B$15,Parameters!$B$16)) -> 2 | G12: =COUNTIFS($B$2:$B$132,B12,$C$2:$C$132,C12,$F$2:$F$132,">"&F12)+COUNTIFS($B$2:$B$132,B12,$C$2:$C$132,C12,$F$2:$F$132,F12,$A$2:$A$132,"<="&A12) -> 3 | H12: =Parameters!$B$20^(G12-1) -> 0.49 | I12: =E12*F12*H12 -> 7.84
A13: 12 | B13: ='Data LLAMA'!B13 -> 5 | C13: ='Data LLAMA'!F13 -> reasoning | D13: =LOWER(TRIM('Data LLAMA'!H13)) -> medium | E13: =IF(ISNUMBER(SEARCH("move_legality",C13)),Parameters!$B$4,IF(ISNUMBER(SEARCH("piece_placement",C13)),Parameters!$B$5,IF(ISNUMBER(SEARCH("material",C13)),Parameters!$B$6,IF(ISNUMBER(SEARCH("piece_relations",C13)),Parameters!$B$7,IF(ISNUMBER(SEARCH("geometry",C13)),Parameters!$B$8,IF(ISNUMBER(SEARCH("reasoning",C13)),Parameters!$B$9,Parameters!$B$10)))))) -> 2 | F13: =IF(D13="major",Parameters!$B$14,IF(D13="medium",Parameters!$B$15,Parameters!$B$16)) -> 2 | G13: =COUNTIFS($B$2:$B$132,B13,$C$2:$C$132,C13,$F$2:$F$132,">"&F13)+COUNTIFS($B$2:$B$132,B13,$C$2:$C$132,C13,$F$2:$F$132,F13,$A$2:$A$132,"<="&A13) -> 6 | H13: =Parameters!$B$20^(G13-1) -> 0.16807 | I13: =E13*F13*H13 -> 0.67228
... A132: 131 | B132: ='Data LLAMA'!B132 -> 20 | C132: ='Data LLAMA'!F132 -> move_legality | D132: =LOWER(TRIM('Data LLAMA'!H132)) -> major | E132: =IF(ISNUMBER(SEARCH("move_legality",C132)),Parameters!$B$4,IF(ISNUMBER(SEARCH("piece_placement",C132)),Parameters!$B$5,IF(ISNUMBER(SEARCH("material",C132)),Parameters!$B$6,IF(ISNUMBER(SEARCH("piece_relations",C132)),Parameters!$B$7,IF(ISNUMBER(SEARCH("geometry",C132)),Parameters!$B$8,IF(ISNUMBER(SEARCH("reasoning",C132)),Parameters!$B$9,Parameters!$B$10)))))) -> 8 | F132: =IF(D132="major",Parameters!$B$14,IF(D132="medium",Parameters!$B$15,Parameters!$B$16)) -> 3 | G132: =COUNTIFS($B$2:$B$132,B132,$C$2:$C$132,C132,$F$2:$F$132,">"&F132)+COUNTIFS($B$2:$B$132,B132,$C$2:$C$132,C132,$F$2:$F$132,F132,$A$2:$A$132,"<="&A132) -> 1 | H132: =Parameters!$B$20^(G132-1) -> 1 | I132: =E132*F132*H132 -> 24

Sheet Puzzle Scores LLAMA
A1: Puzzle ID | B1: Hallucinations (count) | C1: P_total (sum of penalties) | D1: Score_p = MAX(0, 100−P_total) | E1: Interpretation
A2: 1 | B2: =COUNTIF('Calculations LLAMA'!$B:$B, A2) -> 3 | C2: =SUMIF('Calculations LLAMA'!$B:$B, A2, 'Calculations LLAMA'!$I:$I) -> 23.4 | D2: =MAX(0,100-C2) -> 76.6 | E2: =IF(D2>=90,"Excellent",IF(D2>=75,"Good",IF(D2>=55,"Acceptable",IF(D2>=35,"Weak","Critic")))) -> Good
A3: 2 | B3: =COUNTIF('Calculations LLAMA'!$B:$B, A3) -> 5 | C3: =SUMIF('Calculations LLAMA'!$B:$B, A3, 'Calculations LLAMA'!$I:$I) -> 51.8 | D3: =MAX(0,100-C3) -> 48.2 | E3: =IF(D3>=90,"Excellent",IF(D3>=75,"Good",IF(D3>=55,"Acceptable",IF(D3>=35,"Weak","Critic")))) -> Weak
A4: 3 | B4: =COUNTIF('Calculations LLAMA'!$B:$B, A4) -> 6 | C4: =SUMIF('Calculations LLAMA'!$B:$B, A4, 'Calculations LLAMA'!$I:$I) -> 27.4724 | D4: =MAX(0,100-C4) -> 72.5276 | E4: =IF(D4>=90,"Excellent",IF(D4>=75,"Good",IF(D4>=55,"Acceptable",IF(D4>=35,"Weak","Critic")))) -> Acceptable
A5: 4 | B5: =COUNTIF('Calculations LLAMA'!$B:$B, A5) -> 7 | C5: =SUMIF('Calculations LLAMA'!$B:$B, A5, 'Calculations LLAMA'!$I:$I) -> 30.94834 | D5: =MAX(0,100-C5) -> 69.05166 | E5: =IF(D5>=90,"Excellent",IF(D5>=75,"Good",IF(D5>=55,"Acceptable",IF(D5>=35,"Weak","Critic")))) -> Acceptable
A6: 5 | B6: =COUNTIF('Calculations LLAMA'!$B:$B, A6) -> 9 | C6: =SUMIF('Calculations LLAMA'!$B:$B, A6, 'Calculations LLAMA'!$I:$I) -> 65.95088 | D6: =MAX(0,100-C6) -> 34.04912 | E6: =IF(D6>=90,"Excellent",IF(D6>=75,"Good",IF(D6>=55,"Acceptable",IF(D6>=35,"Weak","Critic")))) -> Critic
A7: 6 | B7: =COUNTIF('Calculations LLAMA'!$B:$B, A7) -> 7 | C7: =SUMIF('Calculations LLAMA'!$B:$B, A7, 'Calculations LLAMA'!$I:$I) -> 32.97474 | D7: =MAX(0,100-C7) -> 67.02526 | E7: =IF(D7>=90,"Excellent",IF(D7>=75,"Good",IF(D7>=55,"Acceptable",IF(D7>=35,"Weak","Critic")))) -> Acceptable
A8: 7 | B8: =COUNTIF('Calculations LLAMA'!$B:$B, A8) -> 9 | C8: =SUMIF('Calculations LLAMA'!$B:$B, A8, 'Calculations LLAMA'!$I:$I) -> 35.463838 | D8: =MAX(0,100-C8) -> 64.536162 | E8: =IF(D8>=90,"Excellent",IF(D8>=75,"Good",IF(D8>=55,"Acceptable",IF(D8>=35,"Weak","Critic")))) -> Acceptable
A9: 8 | B9: =COUNTIF('Calculations LLAMA'!$B:$B, A9) -> 6 | C9: =SUMIF('Calculations LLAMA'!$B:$B, A9, 'Calculations LLAMA'!$I:$I) -> 56.2 | D9: =MAX(0,100-C9) -> 43.8 | E9: =IF(D9>=90,"Excellent",IF(D9>=75,"Good",IF(D9>=55,"Acceptable",IF(D9>=35,"Weak","Critic")))) -> Weak
A10: 9 | B10: =COUNTIF('Calculations LLAMA'!$B:$B, A10) -> 6 | C10: =SUMIF('Calculations LLAMA'!$B:$B, A10, 'Calculations LLAMA'!$I:$I) -> 41.066 | D10: =MAX(0,100-C10) -> 58.934 | E10: =IF(D10>=90,"Excellent",IF(D10>=75,"Good",IF(D10>=55,"Acceptable",IF(D10>=35,"Weak","Critic")))) -> Acceptable
A11: 10 | B11: =COUNTIF('Calculations LLAMA'!$B:$B, A11) -> 6 | C11: =SUMIF('Calculations LLAMA'!$B:$B, A11, 'Calculations LLAMA'!$I:$I) -> 58.4 | D11: =MAX(0,100-C11) -> 41.6 | E11: =IF(D11>=90,"Excellent",IF(D11>=75,"Good",IF(D11>=55,"Acceptable",IF(D11>=35,"Weak","Critic")))) -> Weak
A12: 11 | B12: =COUNTIF('Calculations LLAMA'!$B:$B, A12) -> 2 | C12: =SUMIF('Calculations LLAMA'!$B:$B, A12, 'Calculations LLAMA'!$I:$I) -> 22 | D12: =MAX(0,100-C12) -> 78 | E12: =IF(D12>=90,"Excellent",IF(D12>=75,"Good",IF(D12>=55,"Acceptable",IF(D12>=35,"Weak","Critic")))) -> Good
A13: 12 | B13: =COUNTIF('Calculations LLAMA'!$B:$B, A13) -> 10 | C13: =SUMIF('Calculations LLAMA'!$B:$B, A13, 'Calculations LLAMA'!$I:$I) -> 41.110893 | D13: =MAX(0,100-C13) -> 58.889107 | E13: =IF(D13>=90,"Excellent",IF(D13>=75,"Good",IF(D13>=55,"Acceptable",IF(D13>=35,"Weak","Critic")))) -> Acceptable
... A21: 20 | B21: =COUNTIF('Calculations LLAMA'!$B:$B, A21) -> 14 | C21: =SUMIF('Calculations LLAMA'!$B:$B, A21, 'Calculations LLAMA'!$I:$I) -> 105.72668 | D21: =MAX(0,100-C21) -> 0 | E21: =IF(D21>=90,"Excellent",IF(D21>=75,"Good",IF(D21>=55,"Acceptable",IF(D21>=35,"Weak","Critic")))) -> Critic
A22: MODEL SCORE | C22: =ROUND(AVERAGE(C2:C21),2) -> 45.43 | D22: =ROUND(AVERAGE(D2:D21),2) -> 54.85 | E22: =IF(D22>=90,"Excellent",IF(D22>=75,"Good",IF(D22>=55,"Acceptable",IF(D22>=35,"Weak","Critic")))) -> Weak

Sheet Data QWEN
A1: model | B1: puzzle_id | C1: fen | D1: move | E1: original_claim | F1: hallucination_type | G1: fixed_claim | H1: potential_impact
A2: Qwen 3.5 397B A17B | B2: 1 | C2: 3rk2r/pp3p1p/1q2p1pb/3p4/3Q4/P1N1PB1P/1PP3P1/1R1R2K1 b k - 0 1 | D2: Bxe3 | E2: Ask yourself: What is the value of this sacrifice? | F2: piece_relations | G2: it is not a sacrifice, bishop is protected through x-ray | H2: major
A3: Qwen 3.5 397B A17B | B3: 1 | D3: Bxe3 | E3: We are giving up a Bishop for a pawn | F3: material | G3: bishop is protected, you are not giving it up | H3: medium
A4: Qwen 3.5 397B A17B | B4: 1 | E4: This is a 'Deflection' tactic | F4: reasoning | G4: the main theme of the puzzle is x-ray | H4: minor
A5: Qwen 3.5 397B A17B | B5: 1 | D5: Qxe3 | E5: Forced. White must recapture to avoid losing material or facing a dangerous attack | F5: reasoning | G5: white loses material either way | H5: major
A6: Qwen 3.5 397B A17B | B6: 1 | E6: Previously, the Queen on d4 was blocking your Queen's line of sight from b6 to e3. | F6: reasoning | G6: not really, queen was still controlling e3 thorugh x-ray | H6: medium
A7: Qwen 3.5 397B A17B | B7: 1 | D7: 2.Rh1 | E7: If the King tries to escape, you have still won a pawn and disrupted White's coordination | F7: reasoning | G7: if king moves you just win the queen anyways | H7: medium
A8: Qwen 3.5 397B A17B | B8: 1 | D8: 2...Qxd4?? | E8: Now you win the Queen anyway, as the Bishop on e3 controls important squares | F8: reasoning | G8: subvariation blunder, should have been Bxd4 | H8: major
A9: Qwen 3.5 397B A17B | B9: 1 | D9: Qxe3 | E9: Because the White Queen was forced to move to e3 | F9: move_legality | G9: not forced | H9: medium
A10: Qwen 3.5 397B A17B | B10: 1 | D10: 2...Qxe3 | E10: This is a classic example of an 'Overworked Piece'—the White Queen was trying to defend e3 and block the diagonal simultaneously | F10: reasoning | G10: not the theme of the puzzle + does not really make sense | H10: major
A11: Qwen 3.5 397B A17B | B11: 2 | C11: r2k3r/pp1b1p2/4p1pn/q2pP3/1b5p/1PNB1Q1P/PBP2P2/2KR2R1 w - - 4 20 | D11: Nd5 | E11: If we take, Black recaptures with the e6 pawn | F11: move_legality | G11: black could capture with the queen too | H11: medium
A12: Qwen 3.5 397B A17B | B12: 2 | D12: e6 | E12: This pawn push attacks the bishop on d7 and threatens to open lines directly to the Black King. | F12: reasoning | G12: first part correct, but fails to see the discovered attack | H12: major
A13: Qwen 3.5 397B A17B | B13: 2 | D13: Re8 | E13: Black attempts to defend against the advancing pawn and the opening lines. | F13: reasoning | G13: black choses to save the rook over the bishop on d7; does not explain why black did not move the bishop | H13: major
A14: Qwen 3.5 397B A17B | B14: 2 | D14: Kxd7 | E14: White has transformed a positional advantage into a material win | F14: material | G14: white is a pawn down, sacrifice was not for material gain | H14: major
A15: Qwen 3.5 397B A17B | B15: 3 | C15: 5k2/2nr1pp1/pb5p/1p2PP2/4N1R1/P3P2P/1B2K1P1/8 w - - 0 1 | D15: Kxg7 | E15: Declining the sacrifice would leave Black down a pawn with a shattered king position. | F15: material | G15: would leave black down 2 pawns | H15: major
A16: Qwen 3.5 397B A17B | B16: 3 | D16: Kf8 | E16: The King must move out of check. There is no way to block the Bishop's line. | F16: move_legality | G16: there were several other blocking options | H16: medium
A17: Qwen 3.5 397B A17B | B17: 4 | C17: r2nkb1r/3b1ppp/4pn2/1B2p3/8/4BN2/PPP2PPP/2KR3R w kq - 0 1 | D17: Rd7 | E17: Black's Bishop on d7 is defended by the Knight on d8 | F17: piece_relations | G17: knight does not protect the bishop | H17: major
A18: Qwen 3.5 397B A17B | B18: 4 | D18: Nd7 | E18: This is practically forced; otherwise, Black is simply down a piece. | F18: material | G18: black would be down a pawn | H18: major
A19: Qwen 3.5 397B A17B | B19: 4 | D19: Nd7 | E19: notice where the Knight lands: directly in front of its own King on e8 | F19: geometry | G19: d7 is not in front of e7 | H19: medium
A20: Qwen 3.5 397B A17B | B20: 4 | D20: Rd1 | E20: A quiet move that delivers a thunderbolt | F20: reasoning | G20: not quiet, attacks d7 knight | H20: major
A21: Qwen 3.5 397B A17B | B21: 4 | E21: look at the diagonal and file alignment: White Rook on d1, Black Knight on d7, Black King on e8. This is an Absolute Pin | F21: reasoning | G21: there is an abolute pin, but done by the b5 bishop, not by the d1 rook | H21: major
A22: Qwen 3.5 397B A17B | B22: 4 | D22: Ra5 | E22: When you have a calculated winning sequence, do not be distracted by threats that do not deliver immediate checkmate | F22: reasoning | G22: weird general advice that is not always true | H22: minor
A23: Qwen 3.5 397B A17B | B23: 4 | D23: Bxd7 | E23: We gave up a Rook (5 points) but won a Bishop (3 points) and a Knight (3 points). Net gain: +3 points (a full minor piece) | F23: material | G23: gain from sacrifice is +1 point | H23: major
A24: Qwen 3.5 397B A17B | B24: 5 | C24: 8/1p6/4N1pk/5n2/P7/1P3R2/2r4P/7K b - - 0 1 | D24: Kg2 | E24: Forced. The King must escape the check. | F24: move_legality | G24: blocking is also possible | H24: medium
A25: Qwen 3.5 397B A17B | B25: 5 | D25: Kg2 | E25: Moving to h2 would allow similar tactics | F25: move_legality | G25: Kh2 is illegal | H25: major
A26: Qwen 3.5 397B A17B | B26: 5 | D26: Kf3 | E26: Black is now up a full exchange (Rook vs Knight | F26: material | G26: rook vs knight + pawn | H26: major
A27: Qwen 3.5 397B A17B | B27: 6 | C27: r2r2k1/pb1nbppp/1p2p3/4P3/7q/PBN1B3/1P2QPPP/2RR2K1 w - - 0 1 | D27: Rd4 | E27: This is a classic 'Decoy Sacrifice' setup. | F27: reasoning | G27: there is no sacrifice, the rook is protected by the bishop | H27: major
A28: Qwen 3.5 397B A17B | B28: 6 | D28: Rd4 | E28: We voluntarily offer the Rook to lure the Queen onto a square where she becomes vulnerable to the Bishop. | F28: reasoning | G28: misses the point - the queen is trapped | H28: major
A29: Qwen 3.5 397B A17B | B29: 6 | D29: Qxd4 | E29: In tactical puzzles, when an opponent captures a piece, you must have a specific reason for allowing it | F29: reasoning | G29: true, but completely irrelevant here, the rook was always protected | H29: medium
A30: Qwen 3.5 397B A17B | B30: 6 | D30: Qxd4 | E30: Black wins a Rook temporarily, but fails to see the follow-up. | F30: reasoning | G30: misses the point - the queen is trapped, she'd be lost anyways | H30: major
A31: Qwen 3.5 397B A17B | B31: 6 | D31: Bxd4 | E31: This pattern of 'Lure and Capture' is a fundamental tactical motif. | F31: reasoning | G31: misses puzzle theme completely | H31: major
A32: Qwen 3.5 397B A17B | B32: 7 | C32: 5rk1/3r1p1p/pq4p1/2R1Q3/1p2P2P/3P4/PP1K2P1/5R2 b - - 0 1 | D32: f6 | E32: This is a classic 'Overloaded Defender' pattern. | F32: reasoning | G32: queen is not overloaded, but if attacked she cannot protect the rook from a different square | H32: medium
A33: Qwen 3.5 397B A17B | B33: 7 | D33: Qxc5 | E33: Always check if a piece is overworked before committing to a capture. | F33: reasoning | G33: weird general advice | H33: minor
